{
  "summary": {
    "total_tests": 14,
    "passed": 3,
    "failed": 11,
    "success_rate": 21.428571428571427,
    "timestamp": "2025-09-11T01:00:17.438357"
  },
  "results": [
    {
      "test": "Server Connection",
      "status": "\u274c FAIL",
      "message": "Server not accessible",
      "details": "HTTPConnectionPool(host='192.168.0.3', port=5002): Max retries exceeded with url: / (Caused by NewConnectionError('<urllib3.connection.HTTPConnection object at 0x1047270e0>: Failed to establish a new connection: [Errno 61] Connection refused'))",
      "timestamp": "2025-09-11T01:00:17.433171"
    },
    {
      "test": "Database Connection",
      "status": "\u274c FAIL",
      "message": "Database file not found",
      "details": null,
      "timestamp": "2025-09-11T01:00:17.433225"
    },
    {
      "test": "File Structure: app.py",
      "status": "\u2705 PASS",
      "message": "Path: /Users/anji/Desktop/IntelliAttend/server/app.py",
      "details": null,
      "timestamp": "2025-09-11T01:00:17.433252"
    },
    {
      "test": "File Structure: AuthRepository.kt",
      "status": "\u2705 PASS",
      "message": "Path: /Users/anji/Desktop/IntelliAttend/Mobile App/app/src/main/java/com/intelliattend/student/data/repository/AuthRepository.kt",
      "details": null,
      "timestamp": "2025-09-11T01:00:17.433273"
    },
    {
      "test": "File Structure: intelliattend.db",
      "status": "\u274c FAIL",
      "message": "Path: /Users/anji/Desktop/IntelliAttend/instance/intelliattend.db",
      "details": null,
      "timestamp": "2025-09-11T01:00:17.433284"
    },
    {
      "test": "File Structure: tokens",
      "status": "\u2705 PASS",
      "message": "Path: /Users/anji/Desktop/IntelliAttend/QR_DATA/tokens",
      "details": null,
      "timestamp": "2025-09-11T01:00:17.433294"
    },
    {
      "test": "Faculty Login",
      "status": "\u274c FAIL",
      "message": "Request failed",
      "details": "HTTPConnectionPool(host='192.168.0.3', port=5002): Max retries exceeded with url: /api/faculty/login (Caused by NewConnectionError('<urllib3.connection.HTTPConnection object at 0x104736d50>: Failed to establish a new connection: [Errno 61] Connection refused'))",
      "timestamp": "2025-09-11T01:00:17.434521"
    },
    {
      "test": "Student Login",
      "status": "\u274c FAIL",
      "message": "Request failed",
      "details": "HTTPConnectionPool(host='192.168.0.3', port=5002): Max retries exceeded with url: /api/student/login (Caused by NewConnectionError('<urllib3.connection.HTTPConnection object at 0x104737610>: Failed to establish a new connection: [Errno 61] Connection refused'))",
      "timestamp": "2025-09-11T01:00:17.435632"
    },
    {
      "test": "Student Profile",
      "status": "\u274c FAIL",
      "message": "No student token",
      "details": null,
      "timestamp": "2025-09-11T01:00:17.435649"
    },
    {
      "test": "OTP Generation",
      "status": "\u274c FAIL",
      "message": "No faculty token available",
      "details": null,
      "timestamp": "2025-09-11T01:00:17.435658"
    },
    {
      "test": "Session Creation",
      "status": "\u274c FAIL",
      "message": "No OTP available",
      "details": null,
      "timestamp": "2025-09-11T01:00:17.435662"
    },
    {
      "test": "QR Generation",
      "status": "\u274c FAIL",
      "message": "No session ID available",
      "details": null,
      "timestamp": "2025-09-11T01:00:17.435667"
    },
    {
      "test": "API GET /api/health",
      "status": "\u274c FAIL",
      "message": "Request failed",
      "details": "HTTPConnectionPool(host='192.168.0.3', port=5002): Max retries exceeded with url: /api/health (Caused by NewConnectionError('<urllib3.connection.HTTPConnection object at 0x10703c640>: Failed to establish a new connection: [Errno 61] Connection refused'))",
      "timestamp": "2025-09-11T01:00:17.436903"
    },
    {
      "test": "API GET /api/qr/current/999",
      "status": "\u274c FAIL",
      "message": "Request failed",
      "details": "HTTPConnectionPool(host='192.168.0.3', port=5002): Max retries exceeded with url: /api/qr/current/999 (Caused by NewConnectionError('<urllib3.connection.HTTPConnection object at 0x104703490>: Failed to establish a new connection: [Errno 61] Connection refused'))",
      "timestamp": "2025-09-11T01:00:17.438044"
    }
  ]
}